<?xml version="1.0"?>
<robot name="myfirst">

	<link name="base_link">
    <visual>
      <origin rpy="0.0 0 0" xyz="0.235 0 0"/>
      <geometry>
        <mesh filename="file:///home/mostafa/Desktop/Ziko.dae"/>
      </geometry>
    </visual>
  </link>
  
  <link name="wheel1">
		<visual>
			<geometry>
				<mesh filename="file:///home/mostafa/Desktop/ZikoWheel.dae"/>
			</geometry>
		</visual>
	</link>
	
	<link name="wheel2">
		<visual>
			<geometry>
				<mesh filename="file:///home/mostafa/Desktop/ZikoWheel.dae"/>
			</geometry>
		</visual>
	</link>
	
  <link name="wheel3">
		<visual>
			<geometry>
				<mesh filename="file:///home/mostafa/Desktop/ZikoWheel.dae"/>
			</geometry>
		</visual>
	</link>
	
	<link name="wheel4">
		<visual>
			<geometry>
				<mesh filename="file:///home/mostafa/Desktop/ZikoWheel.dae"/>
			</geometry>
		</visual>
	</link>
	
  <joint name="RWheel1_base" type="continuous">
		<axis xyz="1 0 0"/>
		<parent link="base_link"/>
  	<child link="wheel1"/>
  	<origin xyz="0.275 0.18 -0.16"/>
  </joint>
  
	<joint name="RWheel2_base" type="continuous">
		<axis xyz="1 0 0"/>
  	<parent link="base_link"/>
  	<child link="wheel2"/>
  	<origin xyz="0.275 -0.18 -0.16"/>
  </joint>
  
  <joint name="LWheel1_base" type="continuous">
  	<axis xyz="1 0 0"/>
		<parent link="base_link"/>
  	<child link="wheel3"/>
  	<origin xyz="-0.275 0.18 -0.16"/>
  </joint>
  
	<joint name="LWheel2_base" type="continuous">
  	<axis xyz="1 0 0"/>
  	<parent link="base_link"/>
  	<child link="wheel4"/>
  	<origin xyz="-0.275 -0.18 -0.16"/>
  </joint>
  
</robot>
